<?xml version='1.0'?>

<robot name="eren_bot" xmlns:xacro="http://www.ros.org/wiki/xacro">
    <xacro:include filename="$(find eren_bot_description)/urdf/eren_bot_gazebo.xacro"/>
    
    <link name="robot_footprint">
    </link>
    
    <joint name="robot_footprint_joint" type="fixed">
        <parent link="robot_footprint"/>
        <child link="base_link"/>
    </joint>


    <link name="base_link">
        <inertial>
            <origin xyz="0.0 0.0 0.0"/>
            <mass value="20"/>
            <inertia ixx="0.1" ixy="0.0" ixz="0.0" iyy="0.1" iyz="0.0" izz="0.1"/>
        </inertial>
        <visual name='base_link_visual'>
            <origin xyz="0.0 0.0 0.20" />
            <geometry>
                <box size="0.6 0.45 0.1"/>
            </geometry>
             <material name="">
            <color rgba="1.0 0.0 0.0 1.0"/>
            <texture filename=""/>
        </material>
        </visual>

        <collision name='1'>
            <origin xyz="0.0 0.0 0.2" rpy="0.0 0.0 0.0"/>
            <geometry>
                <box size="0.6 0.45 0.1"/>
            </geometry>
        </collision>
        <visual name='base_link_visual'>
            <origin xyz="-0.10 0.0 0.30" />
            <geometry>
                <box size="0.4 0.45 0.1"/>
            </geometry>
             <material name="">
            <color rgba="1.0 0.0 0.0 1.0"/>
            <texture filename=""/>
        </material>
        </visual>

        <collision name='2'>
            <origin xyz="-0.10 0.0 0.30" />
            <geometry>
                <box size="0.4 0.45 0.1"/>
            </geometry>
        </collision>    
        </link>

    <link name="front_right_wheel">    
    <inertial>
      <mass value="5"/>
      <origin rpy="0 0 0" xyz="0 0 0"/>
      <inertia ixx="0.1" ixy="0" ixz="0" iyy="0.1" iyz="0" izz="0.1"/>
    </inertial>
    
    <collision name="front_right_wheel_collision">
      <origin rpy="0 1.5707 1.5707" xyz="0 0 0" />
      <geometry>
        <cylinder length="0.05" radius="0.1"/>
      </geometry>
    </collision>
    
    <visual name="front_right_wheel_visual">
      <origin rpy="0 1.5707 1.5707" xyz="0 0 0"/>
      <geometry>
        <cylinder length="0.05" radius="0.1"/>
      </geometry>   
     <material name="">
            <color rgba="0.0 1.0 0.0 1.0"/>
            <texture filename=""/>
        </material>
    </visual>
    
  </link>
  <joint name="front_right_wheel_joint" type="continuous">
    <origin rpy="0 0 0" xyz="0.175 -0.25 0.1"/>
    <child link="front_right_wheel" />
    <parent link="base_link"/>
    <axis rpy="0 0 0" xyz="0 1 0"/>
  </joint>   


    <link name="front_left_wheel">    
    <inertial>
      <mass value="5"/>
      <origin rpy="0 0 0" xyz="0 0 0"/>
      <inertia ixx="0.1" ixy="0" ixz="0" iyy="0.1" iyz="0" izz="0.1"/>
    </inertial>
    
    <collision name="front_left_wheel_collision">
      <origin rpy="0 1.5707 1.5707" xyz="0 0 0" />
      <geometry>
        <cylinder length="0.05" radius="0.1"/>
      </geometry>
    </collision>
    
    <visual name="front_left_wheel_visual">
      <origin rpy="0 1.5707 1.5707" xyz="0 0 0"/>
      <geometry>
        <cylinder length="0.05" radius="0.1"/>
      </geometry>   
      <material name="">
            <color rgba="0.0 1.0 0.0 1.0"/>
            <texture filename=""/>
        </material>   
    </visual>
    
  </link>
  <joint name="front_left_wheel_joint" type="continuous">
   <origin rpy="0 0 0" xyz="0.175 0.25 0.1"/>
    <child link="front_left_wheel" />
    <parent link="base_link"/>
    <axis rpy="0 0 0" xyz="0 1 0"/>
  </joint>   

<link name="back_left_wheel">    
    <inertial>
      <mass value="5"/>
      <origin rpy="0 0 0" xyz="0 0 0"/>
      <inertia ixx="0.1" ixy="0" ixz="0" iyy="0.1" iyz="0" izz="0.1"/>
    </inertial>
    
    <collision name="back_left_wheel_collision">
    <origin xyz="0.0 0.0 0.0" rpy="0.0 0.0 0.0"/>
      <geometry>
        <cylinder length="0.05" radius="0.1"/>
      </geometry>
    </collision>
    
    <visual name="back_left_wheel_visual">
      <origin xyz="0.0 0.0 0.0" rpy="0.0 0.0 0.0"/>
      <geometry>
        <cylinder length="0.05" radius="0.1"/>
      </geometry>   
      <material name="">
            <color rgba="0.0 1.0 0.0 1.0"/>
            <texture filename=""/>
        </material> 
    </visual>
    
  </link>
  <joint name="back_left_wheel_joint" type="continuous">
   <origin rpy="0 -1.5707 1.5707" xyz="-0.175 0.25 0.1" />
    <child link="back_left_wheel" />
    <parent link="base_link"/>
    <axis rpy="0 0 0" xyz="0 1 0"/>
  </joint>   

  <link name="back_right_wheel">    
    <inertial>
      <mass value="5"/>
      <origin rpy="0 0 0" xyz="0 0 0"/>
      <inertia ixx="0.1" ixy="0" ixz="0" iyy="0.1" iyz="0" izz="0.1"/>
    </inertial>
    
    <collision name="back_right_wheel_collision">
      <origin xyz="0.0 0.0 0.0" rpy="0.0 0.0 0.0"/>
      <geometry>
        <cylinder length="0.05" radius="0.1"/>
      </geometry>
    </collision>
    
    <visual name="back_right_wheel_visual">
      <origin xyz="0.0 0.0 0.0" rpy="0.0 0.0 0.0"/>
      <geometry>
        <cylinder length="0.05" radius="0.1"/>
      </geometry>   
      <material name="">
            <color rgba="0.0 1.0 0.0 1.0"/>
            <texture filename=""/>
        </material> 
    </visual>
    
  </link>
  <joint name="back_right_wheel_joint" type="continuous">
    <origin rpy="0 -1.5707 1.5707" xyz="-0.175 -0.25 0.1" />
    <child link="back_right_wheel" />
    <parent link="base_link"/>
    <axis rpy="0 0 0" xyz="0 1 0"/>
  </joint>   


  <!-- Kamera Linki -->
  <link name="camera_link">
      <inertial>
          <origin xyz="0.0 0.0 0.0" rpy="0.0 0.0 0.0"/>
          <mass value="0.1"/>
          <inertia ixx="0.0" ixy="0.0" ixz="0.0" iyy="0.0" iyz="0.0" izz="0.0"/>
      </inertial>
      <visual>
          <origin xyz="0 0 0" rpy="0 0 0"/>
          <geometry>
              <box size="0.05 0.05 0.05"/>
          </geometry>
          <material name="Gazebo/Blue">
              <color rgba="0.0 0.0 1.0 1.0"/>
          </material>
      </visual>
      <collision>
          <origin xyz="0.0 0.0 0.0" rpy="0.0 0.0 0.0"/>
          <geometry>
              <box size="0.05 0.05 0.05"/>
          </geometry>
      </collision>
  </link>

  <!-- Kamera Joint'i -->
  <joint name="camera_joint" type="fixed">
      <parent link="base_link"/>
      <child link="camera_link"/>
      <origin xyz="0.3 0.0 0.3" rpy="0 0 0"/>
  </joint>


   <!-- <link name="lidar_link">
        <inertial>
            <origin xyz="0.0 0.0 0.0" rpy="0.0 0.0 0.0"/>
            <mass value="0.1"/>
            <inertia ixx="0.0" ixy="0.0" ixz="0.0" iyy="0.0" iyz="0.0" izz="0.0"/>
        </inertial>
        <visual name="lidar_link_visual">
            <origin xyz="0.0 0.0 0.0" rpy="0.0 0.0 0.0"/>
            <geometry>
              <mesh filename="package://diffrobot_description/meshes/lidar_link.STL"/>
            </geometry>
            <material name="">
                <color rgba="0.0 0.0 1.0 1.0"/>
                <texture filename=""/>
            </material>
        </visual>
        <collision>
            <origin xyz="0.0 0.0 0.0" rpy="0.0 0.0 0.0"/>
            <geometry>
                 <box size="0.1 0.1 0.1"/>
            </geometry>
        </collision>
    </link>

    <joint name="lidar_joint" type="fixed">
         <origin xyz="0.25 0.0 0.28" rpy="1.5708 0.0 1.5708"/>
        <parent link="base_link"/>
        <child link="lidar_link"/>
    </joint>

<link name="laser_data_link">
    
</link>

<joint name="laser_data_joint" type="fixed">
     <origin xyz="0.0 0.0 0.0" rpy="0.0 -1.5708 -1.5708"/>
    <parent link="lidar_link"/>
    <child link="laser_data_link"/>
</joint> -->

</robot>
